Workbook

Sheet Summary
A1: Driver Complaint Analysis — Week 39 (21–27 Sep 2026)
A2: Source: Driver_complaint_W39.xlsx (Sheet5, 498 rows). All figures below are live formulas on the "Cases" sheet.
A4: Headline KPIs | I4: Key findings & recommendations
A5: Total cases | B5: =COUNTA(Cases!$B$2:$B$499) | I5: 1. Fake Fail dominates: 341 of 498 cases (68%). Fake Success (58) and Wrong Address (55) follow — together these three are 91% of complaints.
A6: Unique TIDs | B6: =COUNTA('Metabase Lookup'!A2:A480)
A7: Fake Fail share | B7: =COUNTIF(Cases!$N$2:$N$499,"Fake Fail")/B5
A8: Driver not identified (OPS account) | B8: =COUNTIF(Cases!$J$2:$J$499,"OPS (generic hub account)")/B5 | I8: 2. The call is the weak point: 238 Fake Fails (70%) fail on call evidence — no call log, call not connected / <3 attempts, wrong number, or an invalid call log. Only 29 fail on location alone, though 103 (30%) also have a bad location/site photo.
A9: TIDs logged 2+ times | B9: =COUNTIF('Metabase Lookup'!G2:G480,">1")
A10: Hubs with complaints | B10: =COUNTA('Hub Scorecard'!B5:B107)
A11: Cases with prior tag (Metabase) | B11: =IF(COUNTIF(Cases!$Y$2:$Y$499,"Pending")=B5,"Pending sync",COUNTIF(Cases!$Y$2:$Y$499,"Yes")) | C11: ← fills in once Metabase results are pasted into "Metabase Lookup" | I11: 3. Half the cases can't be pinned on a driver: 236 (47%) were filed against a generic hub OPS account (e.g. OPS - PJY, GLG - OPS - ENGKU). PJY's 29 cases are 100% Fake Fail and all under 'OPS - PJY' — this looks like hub-level bulk failing, not individual drivers.
A12: Prior-tag rate | B12: =IF(ISNUMBER(B11),B11/(B5-COUNTIF(Cases!$Y$2:$Y$499,"Pending")),"Pending sync")
A14: Complaints by type | E14: Fake Fail root cause (from details text) | I14: 4. Concentrated in a few hubs: the top 5 hubs (PJY 29, GLG 25, KEM 24, OUG 24, BTR 23) account for 25% of cases across 103 hubs. Klang Valley (40%) and Southern (31%) make up 71%.
A15: Complaint Type | B15: Cases | C15: % of Total | E15: Root Cause | F15: Cases | G15: % of Fake Fail
A16: Fake Fail | B16: =COUNTIF(Cases!$N$2:$N$499,A16) | C16: =B16/SUM(B$16:B$25) | E16: No call / call log missing | F16: =COUNTIF(Cases!$O$2:$O$499,E16) | G16: =F16/SUM(F$16:F$24)
A17: Fake Success | B17: =COUNTIF(Cases!$N$2:$N$499,A17) | C17: =B17/SUM(B$16:B$25) | E17: Call not connected / no response | F17: =COUNTIF(Cases!$O$2:$O$499,E17) | G17: =F17/SUM(F$16:F$24) | I17: 5. Repeat parcels: 17 TIDs were logged 2+ times (36 rows). Some are double entries minutes apart; others (e.g. WNJMY00006942908, logged 4× as Fake Fail + POR) show the first complaint did not fix the parcel.
A18: Deliver to Wrong Address | B18: =COUNTIF(Cases!$N$2:$N$499,A18) | C18: =B18/SUM(B$16:B$25) | E18: Invalid POD (no detail) | F18: =COUNTIF(Cases!$O$2:$O$499,E18) | G18: =F18/SUM(F$16:F$24)
A19: Pull Out Route (POR) | B19: =COUNTIF(Cases!$N$2:$N$499,A19) | C19: =B19/SUM(B$16:B$25) | E19: Wrong number called | F19: =COUNTIF(Cases!$O$2:$O$499,E19) | G19: =F19/SUM(F$16:F$24)
A20: Failed pick-up | B20: =COUNTIF(Cases!$N$2:$N$499,A20) | C20: =B20/SUM(B$16:B$25) | E20: Invalid call log (unspecified) | F20: =COUNTIF(Cases!$O$2:$O$499,E20) | G20: =F20/SUM(F$16:F$24) | I20: 6. Repeat drivers: 34 named drivers have 2+ complaints; BKW - ID - KENNETH leads with 7, then BTR - ID - KHAIRAN (4). See Driver Watchlist.
A21: Parcel Dumping | B21: =COUNTIF(Cases!$N$2:$N$499,A21) | C21: =B21/SUM(B$16:B$25) | E21: Invalid location / site photo | F21: =COUNTIF(Cases!$O$2:$O$499,E21) | G21: =F21/SUM(F$16:F$24)
A22: Lost Item | B22: =COUNTIF(Cases!$N$2:$N$499,A22) | C22: =B22/SUM(B$16:B$25) | E22: Customer disputes attempt | F22: =COUNTIF(Cases!$O$2:$O$499,E22) | G22: =F22/SUM(F$16:F$24)
A23: CMI (Can't Make It) | B23: =COUNTIF(Cases!$N$2:$N$499,A23) | C23: =B23/SUM(B$16:B$25) | E23: Recycled / manipulated POD | F23: =COUNTIF(Cases!$O$2:$O$499,E23) | G23: =F23/SUM(F$16:F$24) | I23: 7. Volume is front-loaded: Monday 21 Sep had 114 cases (backlog from the weekend), declining to 55 on Saturday.
A24: Rude Behavior | B24: =COUNTIF(Cases!$N$2:$N$499,A24) | C24: =B24/SUM(B$16:B$25) | E24: Type mismatch (detail not Fake Fail) | F24: =COUNTIF(Cases!$O$2:$O$499,E24) | G24: =F24/SUM(F$16:F$24)
A25: COD Related | B25: =COUNTIF(Cases!$N$2:$N$499,A25) | C25: =B25/SUM(B$16:B$25)
I26: 8. Recommended actions: (a) require the actual driver name — lookup by Route ID — instead of OPS accounts; (b) enforce the POD standard (3 connected call attempts at different times, customer's own number, identifiable site photo) at hub level, starting with PJY, GLG, KEM, OUG, BTR; (c) audit OPS bulk-fail practice at PJY/NSJ/KEM; (d) coach/escalate Watchlist drivers; (e) convert free-text form fields to dropdowns (see Data Quality).
A27: Complaints by region | E27: Who the complaint was filed against
A28: Region | B28: Cases | C28: % of Total | E28: Driver Account Type | F28: Cases | G28: % of Total
A29: KV | B29: =COUNTIF(Cases!$G$2:$G$499,A29) | C29: =B29/SUM(B$29:B$36) | E29: OPS (generic hub account) | F29: =COUNTIF(Cases!$J$2:$J$499,E29) | G29: =F29/SUM(F$29:F$37) | I29: 9. Metabase prior-tag and Global ID are pending: the Metabase account used had no database access. Paste the query results into 'Metabase Lookup' and KPIs B11:B12 fill in automatically (see How to Sync).
A30: Southern | B30: =COUNTIF(Cases!$G$2:$G$499,A30) | C30: =B30/SUM(B$29:B$36) | E30: ID (named driver) | F30: =COUNTIF(Cases!$J$2:$J$499,E30) | G30: =F30/SUM(F$29:F$37)
A31: Northern | B31: =COUNTIF(Cases!$G$2:$G$499,A31) | C31: =B31/SUM(B$29:B$36) | E31: Name only (no hub/code) | F31: =COUNTIF(Cases!$J$2:$J$499,E31) | G31: =F31/SUM(F$29:F$37)
A32: East MY | B32: =COUNTIF(Cases!$G$2:$G$499,A32) | C32: =B32/SUM(B$29:B$36) | E32: Multiple drivers | F32: =COUNTIF(Cases!$J$2:$J$499,E32) | G32: =F32/SUM(F$29:F$37)
A33: North West | B33: =COUNTIF(Cases!$G$2:$G$499,A33) | C33: =B33/SUM(B$29:B$36) | E33: HR (named) | F33: =COUNTIF(Cases!$J$2:$J$499,E33) | G33: =F33/SUM(F$29:F$37)
A34: South West | B34: =COUNTIF(Cases!$G$2:$G$499,A34) | C34: =B34/SUM(B$29:B$36) | E34: HD (named) | F34: =COUNTIF(Cases!$J$2:$J$499,E34) | G34: =F34/SUM(F$29:F$37)
A35: North East | B35: =COUNTIF(Cases!$G$2:$G$499,A35) | C35: =B35/SUM(B$29:B$36) | E35: FM (first-mile) | F35: =COUNTIF(Cases!$J$2:$J$499,E35) | G35: =F35/SUM(F$29:F$37)
A36: Eastern | B36: =COUNTIF(Cases!$G$2:$G$499,A36) | C36: =B36/SUM(B$29:B$36) | E36: IR (named) | F36: =COUNTIF(Cases!$J$2:$J$499,E36) | G36: =F36/SUM(F$29:F$37)
E37: Other coded | F37: =COUNTIF(Cases!$J$2:$J$499,E37) | G37: =F37/SUM(F$29:F$37)
A39: Daily trend (date logged) | E39: Cases keyed in by agent
A40: Date | B40: Cases | C40: % of Total | E40: Agent | F40: Cases | G40: % of Total
A41: 46286 | B41: =COUNTIF(Cases!$E$2:$E$499,A41) | C41: =B41/SUM(B$41:B$47) | E41: Putri | F41: =COUNTIF(Cases!$S$2:$S$499,E41) | G41: =F41/SUM(F$41:F$59)
A42: 46287 | B42: =COUNTIF(Cases!$E$2:$E$499,A42) | C42: =B42/SUM(B$41:B$47) | E42: Zati | F42: =COUNTIF(Cases!$S$2:$S$499,E42) | G42: =F42/SUM(F$41:F$59)
A43: 46288 | B43: =COUNTIF(Cases!$E$2:$E$499,A43) | C43: =B43/SUM(B$41:B$47) | E43: Naveen | F43: =COUNTIF(Cases!$S$2:$S$499,E43) | G43: =F43/SUM(F$41:F$59)
...

Sheet Cases
A1: Case # | B1: Tracking ID | C1: CRM Case ID | D1: Logged At | E1: Date | F1: Day | G1: Region | H1: Hub | I1: Driver(s) | J1: Driver Account Type | K1: Route ID(s) | L1: # Routes | M1: Driver Type | N1: Complaint Type | O1: Fake Fail Root Cause | P1: Location Evidence Issue | Q1: Failed by OPS | R1: Complaint Details | S1: Keyed In By | T1: Times TID Logged (W39) | U1: Driver Complaints (W39) | V1: Global ID | W1: Prior Tag Count | X1: Prior Tags | Y1: Has Prior Tag? | Z1: Data Quality Flags
A2: 1 | B2: TNGE126027128651727000 | C2: 262162627794 | D2: 46286.394 | E2: 46286 | F2: Mon | G2: KV | H2: WMJ | I2: WMJ - ID - MUHAMMAD EFENDY | J2: ID (named driver) | K2: 91838155 | L2: 1 | M2: LM | N2: Fake Success | R2: The driver delivered the parcel after the customer made complaint | S2: Naveen | T2: =COUNTIF($B$2:$B$499,B2) | U2: =COUNTIF($I$2:$I$499,I2) | V2: =IF(ISNA(MATCH(B2,'Metabase Lookup'!$A:$A,0)),"Not found",IF(INDEX('Metabase Lookup'!$B:$B,MATCH(B2,'Metabase Lookup'!$A:$A,0))="","Pending",INDEX('Metabase Lookup'!$B:$B,MATCH(B2,'Metabase Lookup'!$A:$A,0)))) | W2: =IF(ISNA(MATCH(B2,'Metabase Lookup'!$A:$A,0)),"Not found",IF(INDEX('Metabase Lookup'!$C:$C,MATCH(B2,'Metabase Lookup'!$A:$A,0))="","Pending",INDEX('Metabase Lookup'!$C:$C,MATCH(B2,'Metabase Lookup'!$A:$A,0)))) | X2: =IF(ISNA(MATCH(B2,'Metabase Lookup'!$A:$A,0)),"",IF(INDEX('Metabase Lookup'!$D:$D,MATCH(B2,'Metabase Lookup'!$A:$A,0))="","",INDEX('Metabase Lookup'!$D:$D,MATCH(B2,'Metabase Lookup'!$A:$A,0)))) | Y2: =IF(ISNUMBER(W2),IF(W2>0,"Yes","No"),"Pending")
A3: 2 | B3: ZMP299487945-2851 | C3: 260912621851 | D3: 46286.403 | E3: 46286 | F3: Mon | G3: Southern | H3: KLI | I3: KLI - ID - NURIZZAH | J3: ID (named driver) | K3: 91832320 | L3: 1 | M3: LM | N3: Fake Success | R3: The driver delivered the parcel after the customer made complaint | S3: Naveen | T3: =COUNTIF($B$2:$B$499,B3) | U3: =COUNTIF($I$2:$I$499,I3) | V3: =IF(ISNA(MATCH(B3,'Metabase Lookup'!$A:$A,0)),"Not found",IF(INDEX('Metabase Lookup'!$B:$B,MATCH(B3,'Metabase Lookup'!$A:$A,0))="","Pending",INDEX('Metabase Lookup'!$B:$B,MATCH(B3,'Metabase Lookup'!$A:$A,0)))) | W3: =IF(ISNA(MATCH(B3,'Metabase Lookup'!$A:$A,0)),"Not found",IF(INDEX('Metabase Lookup'!$C:$C,MATCH(B3,'Metabase Lookup'!$A:$A,0))="","Pending",INDEX('Metabase Lookup'!$C:$C,MATCH(B3,'Metabase Lookup'!$A:$A,0)))) | X3: =IF(ISNA(MATCH(B3,'Metabase Lookup'!$A:$A,0)),"",IF(INDEX('Metabase Lookup'!$D:$D,MATCH(B3,'Metabase Lookup'!$A:$A,0))="","",INDEX('Metabase Lookup'!$D:$D,MATCH(B3,'Metabase Lookup'!$A:$A,0)))) | Y3: =IF(ISNUMBER(W3),IF(W3>0,"Yes","No"),"Pending") | Z3: TID had stray spaces/line breaks (cleaned)
A4: 3 | B4: TNGE126027145702566000 | C4: 268162624947 | D4: 46286.404 | E4: 46286 | F4: Mon | G4: Southern | H4: KLI | I4: KLI - ID - NURULAZIERAH | J4: ID (named driver) | K4: 91840248 | L4: 1 | M4: LM | N4: Deliver to Wrong Address | R4: the driver delivered the parcel to wrong address instead of customers address | S4: Naveen | T4: =COUNTIF($B$2:$B$499,B4) | U4: =COUNTIF($I$2:$I$499,I4) | V4: =IF(ISNA(MATCH(B4,'Metabase Lookup'!$A:$A,0)),"Not found",IF(INDEX('Metabase Lookup'!$B:$B,MATCH(B4,'Metabase Lookup'!$A:$A,0))="","Pending",INDEX('Metabase Lookup'!$B:$B,MATCH(B4,'Metabase Lookup'!$A:$A,0)))) | W4: =IF(ISNA(MATCH(B4,'Metabase Lookup'!$A:$A,0)),"Not found",IF(INDEX('Metabase Lookup'!$C:$C,MATCH(B4,'Metabase Lookup'!$A:$A,0))="","Pending",INDEX('Metabase Lookup'!$C:$C,MATCH(B4,'Metabase Lookup'!$A:$A,0)))) | X4: =IF(ISNA(MATCH(B4,'Metabase Lookup'!$A:$A,0)),"",IF(INDEX('Metabase Lookup'!$D:$D,MATCH(B4,'Metabase Lookup'!$A:$A,0))="","",INDEX('Metabase Lookup'!$D:$D,MATCH(B4,'Metabase Lookup'!$A:$A,0)))) | Y4: =IF(ISNUMBER(W4),IF(W4>0,"Yes","No"),"Pending")
A5: 4 | B5: NVIDSPMLL000000202 | C5: 267822638198 | D5: 46286.405 | E5: 46286 | F5: Mon | G5: Northern | H5: BKM | I5: BKM - ID - FIKRI | J5: ID (named driver) | K5: 91851116 | L5: 1 | M5: LM | N5: Fake Fail | O5: Wrong number called | P5: No | Q5: No | R5: invalid POD. No contact number show in the whatapps attachment | S5: Hartini | T5: =COUNTIF($B$2:$B$499,B5) | U5: =COUNTIF($I$2:$I$499,I5) | V5: =IF(ISNA(MATCH(B5,'Metabase Lookup'!$A:$A,0)),"Not found",IF(INDEX('Metabase Lookup'!$B:$B,MATCH(B5,'Metabase Lookup'!$A:$A,0))="","Pending",INDEX('Metabase Lookup'!$B:$B,MATCH(B5,'Metabase Lookup'!$A:$A,0)))) | W5: =IF(ISNA(MATCH(B5,'Metabase Lookup'!$A:$A,0)),"Not found",IF(INDEX('Metabase Lookup'!$C:$C,MATCH(B5,'Metabase Lookup'!$A:$A,0))="","Pending",INDEX('Metabase Lookup'!$C:$C,MATCH(B5,'Metabase Lookup'!$A:$A,0)))) | X5: =IF(ISNA(MATCH(B5,'Metabase Lookup'!$A:$A,0)),"",IF(INDEX('Metabase Lookup'!$D:$D,MATCH(B5,'Metabase Lookup'!$A:$A,0))="","",INDEX('Metabase Lookup'!$D:$D,MATCH(B5,'Metabase Lookup'!$A:$A,0)))) | Y5: =IF(ISNUMBER(W5),IF(W5>0,"Yes","No"),"Pending")
A6: 5 | B6: TNGDV2609146889176270 | C6: 260932628324 | D6: 46286.412 | E6: 46286 | F6: Mon | G6: KV | H6: PCK | I6: PCK - ID - AFIQAH MADZLIN | J6: ID (named driver) | K6: 91829537 | L6: 1 | M6: LM | N6: Deliver to Wrong Address | R6: the driver delivered the parcel to wrong address instead of customers address | S6: Naveen | T6: =COUNTIF($B$2:$B$499,B6) | U6: =COUNTIF($I$2:$I$499,I6) | V6: =IF(ISNA(MATCH(B6,'Metabase Lookup'!$A:$A,0)),"Not found",IF(INDEX('Metabase Lookup'!$B:$B,MATCH(B6,'Metabase Lookup'!$A:$A,0))="","Pending",INDEX('Metabase Lookup'!$B:$B,MATCH(B6,'Metabase Lookup'!$A:$A,0)))) | W6: =IF(ISNA(MATCH(B6,'Metabase Lookup'!$A:$A,0)),"Not found",IF(INDEX('Metabase Lookup'!$C:$C,MATCH(B6,'Metabase Lookup'!$A:$A,0))="","Pending",INDEX('Metabase Lookup'!$C:$C,MATCH(B6,'Metabase Lookup'!$A:$A,0)))) | X6: =IF(ISNA(MATCH(B6,'Metabase Lookup'!$A:$A,0)),"",IF(INDEX('Metabase Lookup'!$D:$D,MATCH(B6,'Metabase Lookup'!$A:$A,0))="","",INDEX('Metabase Lookup'!$D:$D,MATCH(B6,'Metabase Lookup'!$A:$A,0)))) | Y6: =IF(ISNUMBER(W6),IF(W6>0,"Yes","No"),"Pending")
A7: 6 | B7: FAEYE1546375134655770624 | C7: 264842649115 | D7: 46286.416 | E7: 46286 | F7: Mon | G7: Northern | H7: BTS | I7: BTS - OPS - PINANG TUNGGAL | J7: OPS (generic hub account) | K7: 91845173 | L7: 1 | M7: LM | N7: Fake Fail | O7: Wrong number called | P7: No | Q7: No | R7: Wrong customer phone number in the POD | S7: Daus | T7: =COUNTIF($B$2:$B$499,B7) | U7: =COUNTIF($I$2:$I$499,I7) | V7: =IF(ISNA(MATCH(B7,'Metabase Lookup'!$A:$A,0)),"Not found",IF(INDEX('Metabase Lookup'!$B:$B,MATCH(B7,'Metabase Lookup'!$A:$A,0))="","Pending",INDEX('Metabase Lookup'!$B:$B,MATCH(B7,'Metabase Lookup'!$A:$A,0)))) | W7: =IF(ISNA(MATCH(B7,'Metabase Lookup'!$A:$A,0)),"Not found",IF(INDEX('Metabase Lookup'!$C:$C,MATCH(B7,'Metabase Lookup'!$A:$A,0))="","Pending",INDEX('Metabase Lookup'!$C:$C,MATCH(B7,'Metabase Lookup'!$A:$A,0)))) | X7: =IF(ISNA(MATCH(B7,'Metabase Lookup'!$A:$A,0)),"",IF(INDEX('Metabase Lookup'!$D:$D,MATCH(B7,'Metabase Lookup'!$A:$A,0))="","",INDEX('Metabase Lookup'!$D:$D,MATCH(B7,'Metabase Lookup'!$A:$A,0)))) | Y7: =IF(ISNUMBER(W7),IF(W7>0,"Yes","No"),"Pending") | Z7: Driver not identified (OPS account)
A8: 7 | B8: NVMYSOUPE000000897 | C8: 260062621768 | D8: 46286.417 | E8: 46286 | F8: Mon | G8: Northern | H8: SPT | I8: SPT - ID - NORHAZANI | J8: ID (named driver) | K8: 91833029 | L8: 1 | M8: LM | N8: Deliver to Wrong Address | R8: the driver delivered the parcel to wrong address instead of customers address | S8: Naveen | T8: =COUNTIF($B$2:$B$499,B8) | U8: =COUNTIF($I$2:$I$499,I8) | V8: =IF(ISNA(MATCH(B8,'Metabase Lookup'!$A:$A,0)),"Not found",IF(INDEX('Metabase Lookup'!$B:$B,MATCH(B8,'Metabase Lookup'!$A:$A,0))="","Pending",INDEX('Metabase Lookup'!$B:$B,MATCH(B8,'Metabase Lookup'!$A:$A,0)))) | W8: =IF(ISNA(MATCH(B8,'Metabase Lookup'!$A:$A,0)),"Not found",IF(INDEX('Metabase Lookup'!$C:$C,MATCH(B8,'Metabase Lookup'!$A:$A,0))="","Pending",INDEX('Metabase Lookup'!$C:$C,MATCH(B8,'Metabase Lookup'!$A:$A,0)))) | X8: =IF(ISNA(MATCH(B8,'Metabase Lookup'!$A:$A,0)),"",IF(INDEX('Metabase Lookup'!$D:$D,MATCH(B8,'Metabase Lookup'!$A:$A,0))="","",INDEX('Metabase Lookup'!$D:$D,MATCH(B8,'Metabase Lookup'!$A:$A,0)))) | Y8: =IF(ISNUMBER(W8),IF(W8>0,"Yes","No"),"Pending")
A9: 8 | B9: TESMX1550062495809400832 | C9: 266782640335 | D9: 46286.419 | E9: 46286 | F9: Mon | G9: Southern | H9: GMR | I9: GMR - ID - HAMID | GMR - ID - NAJIHAH | J9: Multiple drivers | K9: 91841554, 91848717 | L9: 2 | M9: LM | N9: Fake Fail | O9: Recycled / manipulated POD | P9: No | Q9: No | R9: Driver manipulated POD, using same POD | S9: Syak | T9: =COUNTIF($B$2:$B$499,B9) | U9: =COUNTIF($I$2:$I$499,I9) | V9: =IF(ISNA(MATCH(B9,'Metabase Lookup'!$A:$A,0)),"Not found",IF(INDEX('Metabase Lookup'!$B:$B,MATCH(B9,'Metabase Lookup'!$A:$A,0))="","Pending",INDEX('Metabase Lookup'!$B:$B,MATCH(B9,'Metabase Lookup'!$A:$A,0)))) | W9: =IF(ISNA(MATCH(B9,'Metabase Lookup'!$A:$A,0)),"Not found",IF(INDEX('Metabase Lookup'!$C:$C,MATCH(B9,'Metabase Lookup'!$A:$A,0))="","Pending",INDEX('Metabase Lookup'!$C:$C,MATCH(B9,'Metabase Lookup'!$A:$A,0)))) | X9: =IF(ISNA(MATCH(B9,'Metabase Lookup'!$A:$A,0)),"",IF(INDEX('Metabase Lookup'!$D:$D,MATCH(B9,'Metabase Lookup'!$A:$A,0))="","",INDEX('Metabase Lookup'!$D:$D,MATCH(B9,'Metabase Lookup'!$A:$A,0)))) | Y9: =IF(ISNUMBER(W9),IF(W9>0,"Yes","No"),"Pending") | Z9: Multiple drivers in one row; Multiple route IDs
A10: 9 | B10: TNGSB125896319766994000 | C10: 268122622312 | D10: 46286.432 | E10: 46286 | F10: Mon | G10: Southern | H10: LKN | I10: LKN - ID - OPS | J10: OPS (generic hub account) | K10: 91835040 | L10: 1 | M10: LM | N10: Fake Fail | O10: No call / call log missing | P10: No | Q10: No | R10: driver attach invalid pod and no call log attach | S10: Zati | T10: =COUNTIF($B$2:$B$499,B10) | U10: =COUNTIF($I$2:$I$499,I10) | V10: =IF(ISNA(MATCH(B10,'Metabase Lookup'!$A:$A,0)),"Not found",IF(INDEX('Metabase Lookup'!$B:$B,MATCH(B10,'Metabase Lookup'!$A:$A,0))="","Pending",INDEX('Metabase Lookup'!$B:$B,MATCH(B10,'Metabase Lookup'!$A:$A,0)))) | W10: =IF(ISNA(MATCH(B10,'Metabase Lookup'!$A:$A,0)),"Not found",IF(INDEX('Metabase Lookup'!$C:$C,MATCH(B10,'Metabase Lookup'!$A:$A,0))="","Pending",INDEX('Metabase Lookup'!$C:$C,MATCH(B10,'Metabase Lookup'!$A:$A,0)))) | X10: =IF(ISNA(MATCH(B10,'Metabase Lookup'!$A:$A,0)),"",IF(INDEX('Metabase Lookup'!$D:$D,MATCH(B10,'Metabase Lookup'!$A:$A,0))="","",INDEX('Metabase Lookup'!$D:$D,MATCH(B10,'Metabase Lookup'!$A:$A,0)))) | Y10: =IF(ISNUMBER(W10),IF(W10>0,"Yes","No"),"Pending") | Z10: Driver not identified (OPS account)
A11: 10 | B11: NVMYTRADE014219299 | C11: 260932629751 | D11: 46286.435 | E11: 46286 | F11: Mon | G11: North West | H11: SAR | I11: SAR - OPS - ROUTE OPS | J11: OPS (generic hub account) | K11: 91827333 | L11: 1 | M11: LM | N11: Fake Fail | O11: Invalid location / site photo | P11: Yes | Q11: No | R11: driver attach wrong location | S11: Zati | T11: =COUNTIF($B$2:$B$499,B11) | U11: =COUNTIF($I$2:$I$499,I11) | V11: =IF(ISNA(MATCH(B11,'Metabase Lookup'!$A:$A,0)),"Not found",IF(INDEX('Metabase Lookup'!$B:$B,MATCH(B11,'Metabase Lookup'!$A:$A,0))="","Pending",INDEX('Metabase Lookup'!$B:$B,MATCH(B11,'Metabase Lookup'!$A:$A,0)))) | W11: =IF(ISNA(MATCH(B11,'Metabase Lookup'!$A:$A,0)),"Not found",IF(INDEX('Metabase Lookup'!$C:$C,MATCH(B11,'Metabase Lookup'!$A:$A,0))="","Pending",INDEX('Metabase Lookup'!$C:$C,MATCH(B11,'Metabase Lookup'!$A:$A,0)))) | X11: =IF(ISNA(MATCH(B11,'Metabase Lookup'!$A:$A,0)),"",IF(INDEX('Metabase Lookup'!$D:$D,MATCH(B11,'Metabase Lookup'!$A:$A,0))="","",INDEX('Metabase Lookup'!$D:$D,MATCH(B11,'Metabase Lookup'!$A:$A,0)))) | Y11: =IF(ISNUMBER(W11),IF(W11>0,"Yes","No"),"Pending") | Z11: Driver not identified (OPS account)
A12: 11 | B12: NVMYNINJA002502078 | C12: 266882646042 | D12: 46286.44 | E12: 46286 | F12: Mon | G12: Southern | H12: LKN | I12: LKN - ID - SAIFUL | MUA - HR - SYUKRIAHEZAN | J12: Multiple drivers | K12: 91827065, 91844826 | L12: 2 | M12: LM | N12: Fake Fail | O12: Invalid location / site photo | P12: Yes | Q12: No | R12: POD not cust location | S12: Zakwan | T12: =COUNTIF($B$2:$B$499,B12) | U12: =COUNTIF($I$2:$I$499,I12) | V12: =IF(ISNA(MATCH(B12,'Metabase Lookup'!$A:$A,0)),"Not found",IF(INDEX('Metabase Lookup'!$B:$B,MATCH(B12,'Metabase Lookup'!$A:$A,0))="","Pending",INDEX('Metabase Lookup'!$B:$B,MATCH(B12,'Metabase Lookup'!$A:$A,0)))) | W12: =IF(ISNA(MATCH(B12,'Metabase Lookup'!$A:$A,0)),"Not found",IF(INDEX('Metabase Lookup'!$C:$C,MATCH(B12,'Metabase Lookup'!$A:$A,0))="","Pending",INDEX('Metabase Lookup'!$C:$C,MATCH(B12,'Metabase Lookup'!$A:$A,0)))) | X12: =IF(ISNA(MATCH(B12,'Metabase Lookup'!$A:$A,0)),"",IF(INDEX('Metabase Lookup'!$D:$D,MATCH(B12,'Metabase Lookup'!$A:$A,0))="","",INDEX('Metabase Lookup'!$D:$D,MATCH(B12,'Metabase Lookup'!$A:$A,0)))) | Y12: =IF(ISNUMBER(W12),IF(W12>0,"Yes","No"),"Pending") | Z12: Multiple drivers in one row; Multiple route IDs
A13: 12 | B13: MANIR1548139880832774144 | C13: 264712639790 | D13: 46286.441 | E13: 46286 | F13: Mon | G13: Southern | H13: GLG | I13: GLG - OPS - ENGKU | J13: OPS (generic hub account) | K13: 91814193 | L13: 1 | M13: LM | N13: Fake Fail | O13: No call / call log missing | P13: Yes | Q13: No | R13: No call log / location picture | S13: Syafiq | T13: =COUNTIF($B$2:$B$499,B13) | U13: =COUNTIF($I$2:$I$499,I13) | V13: =IF(ISNA(MATCH(B13,'Metabase Lookup'!$A:$A,0)),"Not found",IF(INDEX('Metabase Lookup'!$B:$B,MATCH(B13,'Metabase Lookup'!$A:$A,0))="","Pending",INDEX('Metabase Lookup'!$B:$B,MATCH(B13,'Metabase Lookup'!$A:$A,0)))) | W13: =IF(ISNA(MATCH(B13,'Metabase Lookup'!$A:$A,0)),"Not found",IF(INDEX('Metabase Lookup'!$C:$C,MATCH(B13,'Metabase Lookup'!$A:$A,0))="","Pending",INDEX('Metabase Lookup'!$C:$C,MATCH(B13,'Metabase Lookup'!$A:$A,0)))) | X13: =IF(ISNA(MATCH(B13,'Metabase Lookup'!$A:$A,0)),"",IF(INDEX('Metabase Lookup'!$D:$D,MATCH(B13,'Metabase Lookup'!$A:$A,0))="","",INDEX('Metabase Lookup'!$D:$D,MATCH(B13,'Metabase Lookup'!$A:$A,0)))) | Y13: =IF(ISNUMBER(W13),IF(W13>0,"Yes","No"),"Pending") | Z13: TID had stray spaces/line breaks (cleaned); Driver not identified (OPS account)
A14: 13 | B14: ECFPLXX021424715 | C14: 269792626328 | D14: 46286.442 | E14: 46286 | F14: Mon | G14: KV | H14: RBY | I14: OPS - MAZLI SHAH | J14: OPS (generic hub account) | K14: 91836304 | L14: 1 | M14: LM | N14: Fake Fail | O14: Wrong number called | P14: No | Q14: No | R14: call log attach is not belong to customer | S14: Zati | T14: =COUNTIF($B$2:$B$499,B14) | U14: =COUNTIF($I$2:$I$499,I14) | V14: =IF(ISNA(MATCH(B14,'Metabase Lookup'!$A:$A,0)),"Not found",IF(INDEX('Metabase Lookup'!$B:$B,MATCH(B14,'Metabase Lookup'!$A:$A,0))="","Pending",INDEX('Metabase Lookup'!$B:$B,MATCH(B14,'Metabase Lookup'!$A:$A,0)))) | W14: =IF(ISNA(MATCH(B14,'Metabase Lookup'!$A:$A,0)),"Not found",IF(INDEX('Metabase Lookup'!$C:$C,MATCH(B14,'Metabase Lookup'!$A:$A,0))="","Pending",INDEX('Metabase Lookup'!$C:$C,MATCH(B14,'Metabase Lookup'!$A:$A,0)))) | X14: =IF(ISNA(MATCH(B14,'Metabase Lookup'!$A:$A,0)),"",IF(INDEX('Metabase Lookup'!$D:$D,MATCH(B14,'Metabase Lookup'!$A:$A,0))="","",INDEX('Metabase Lookup'!$D:$D,MATCH(B14,'Metabase Lookup'!$A:$A,0)))) | Y14: =IF(ISNUMBER(W14),IF(W14>0,"Yes","No"),"Pending") | Z14: Driver not identified (OPS account)
A15: 14 | B15: MYNJV70088695348 | C15: 262822628349 | D15: 46286.443 | E15: 46286 | F15: Mon | G15: KV | H15: SLG | I15: OPS - SELAYANG | J15: OPS (generic hub account) | K15: 91808543 | L15: 1 | M15: LM | N15: Fake Fail | O15: Invalid call log (unspecified) | P15: Yes | Q15: No | R15: Driver not attach valid call log and location is under customer address | S15: Zati | T15: =COUNTIF($B$2:$B$499,B15) | U15: =COUNTIF($I$2:$I$499,I15) | V15: =IF(ISNA(MATCH(B15,'Metabase Lookup'!$A:$A,0)),"Not found",IF(INDEX('Metabase Lookup'!$B:$B,MATCH(B15,'Metabase Lookup'!$A:$A,0))="","Pending",INDEX('Metabase Lookup'!$B:$B,MATCH(B15,'Metabase Lookup'!$A:$A,0)))) | W15: =IF(ISNA(MATCH(B15,'Metabase Lookup'!$A:$A,0)),"Not found",IF(INDEX('Metabase Lookup'!$C:$C,MATCH(B15,'Metabase Lookup'!$A:$A,0))="","Pending",INDEX('Metabase Lookup'!$C:$C,MATCH(B15,'Metabase Lookup'!$A:$A,0)))) | X15: =IF(ISNA(MATCH(B15,'Metabase Lookup'!$A:$A,0)),"",IF(INDEX('Metabase Lookup'!$D:$D,MATCH(B15,'Metabase Lookup'!$A:$A,0))="","",INDEX('Metabase Lookup'!$D:$D,MATCH(B15,'Metabase Lookup'!$A:$A,0)))) | Y15: =IF(ISNUMBER(W15),IF(W15>0,"Yes","No"),"Pending") | Z15: Driver not identified (OPS account)
A16: 15 | B16: CHVIN000010477 | C16: 265432641982 | D16: 46286.445 | E16: 46286 | F16: Mon | G16: KV | H16: KLG | I16: KLG -OPS -MUZAFFAR | J16: OPS (generic hub account) | K16: 91844261 | L16: 1 | M16: LM | N16: Fake Fail | O16: No call / call log missing | P16: No | Q16: No | R16: No call log provide and Whatsapp no response | S16: Izzni | T16: =COUNTIF($B$2:$B$499,B16) | U16: =COUNTIF($I$2:$I$499,I16) | V16: =IF(ISNA(MATCH(B16,'Metabase Lookup'!$A:$A,0)),"Not found",IF(INDEX('Metabase Lookup'!$B:$B,MATCH(B16,'Metabase Lookup'!$A:$A,0))="","Pending",INDEX('Metabase Lookup'!$B:$B,MATCH(B16,'Metabase Lookup'!$A:$A,0)))) | W16: =IF(ISNA(MATCH(B16,'Metabase Lookup'!$A:$A,0)),"Not found",IF(INDEX('Metabase Lookup'!$C:$C,MATCH(B16,'Metabase Lookup'!$A:$A,0))="","Pending",INDEX('Metabase Lookup'!$C:$C,MATCH(B16,'Metabase Lookup'!$A:$A,0)))) | X16: =IF(ISNA(MATCH(B16,'Metabase Lookup'!$A:$A,0)),"",IF(INDEX('Metabase Lookup'!$D:$D,MATCH(B16,'Metabase Lookup'!$A:$A,0))="","",INDEX('Metabase Lookup'!$D:$D,MATCH(B16,'Metabase Lookup'!$A:$A,0)))) | Y16: =IF(ISNUMBER(W16),IF(W16>0,"Yes","No"),"Pending") | Z16: Driver not identified (OPS account)
A17: 16 | B17: ZNV252917945-9837 | C17: 262892631421 | D17: 46286.445 | E17: 46286 | F17: Mon | G17: Southern | H17: KLI | I17: OPS - KULAI | J17: OPS (generic hub account) | K17: 91823639 | L17: 1 | M17: LM | N17: Fake Fail | O17: Invalid POD (no detail) | P17: No | Q17: Yes | R17: invalid POD, failed under ops | S17: Yana | T17: =COUNTIF($B$2:$B$499,B17) | U17: =COUNTIF($I$2:$I$499,I17) | V17: =IF(ISNA(MATCH(B17,'Metabase Lookup'!$A:$A,0)),"Not found",IF(INDEX('Metabase Lookup'!$B:$B,MATCH(B17,'Metabase Lookup'!$A:$A,0))="","Pending",INDEX('Metabase Lookup'!$B:$B,MATCH(B17,'Metabase Lookup'!$A:$A,0)))) | W17: =IF(ISNA(MATCH(B17,'Metabase Lookup'!$A:$A,0)),"Not found",IF(INDEX('Metabase Lookup'!$C:$C,MATCH(B17,'Metabase Lookup'!$A:$A,0))="","Pending",INDEX('Metabase Lookup'!$C:$C,MATCH(B17,'Metabase Lookup'!$A:$A,0)))) | X17: =IF(ISNA(MATCH(B17,'Metabase Lookup'!$A:$A,0)),"",IF(INDEX('Metabase Lookup'!$D:$D,MATCH(B17,'Metabase Lookup'!$A:$A,0))="","",INDEX('Metabase Lookup'!$D:$D,MATCH(B17,'Metabase Lookup'!$A:$A,0)))) | Y17: =IF(ISNUMBER(W17),IF(W17>0,"Yes","No"),"Pending") | Z17: Driver not identified (OPS account)
A18: 17 | B18: NVMYTRADE014220750NVMYTRADE014220720 | C18: 266602625524 | D18: 46286.447 | E18: 46286 | F18: Mon | G18: KV | H18: OUG | I18: OPS - OUG | J18: OPS (generic hub account) | K18: 91836443 | L18: 1 | M18: LM | N18: Fake Fail | O18: Wrong number called | P18: No | Q18: No | R18: call log attach not show customer contact number | S18: Zati | T18: =COUNTIF($B$2:$B$499,B18) | U18: =COUNTIF($I$2:$I$499,I18) | V18: =IF(ISNA(MATCH(B18,'Metabase Lookup'!$A:$A,0)),"Not found",IF(INDEX('Metabase Lookup'!$B:$B,MATCH(B18,'Metabase Lookup'!$A:$A,0))="","Pending",INDEX('Metabase Lookup'!$B:$B,MATCH(B18,'Metabase Lookup'!$A:$A,0)))) | W18: =IF(ISNA(MATCH(B18,'Metabase Lookup'!$A:$A,0)),"Not found",IF(INDEX('Metabase Lookup'!$C:$C,MATCH(B18,'Metabase Lookup'!$A:$A,0))="","Pending",INDEX('Metabase Lookup'!$C:$C,MATCH(B18,'Metabase Lookup'!$A:$A,0)))) | X18: =IF(ISNA(MATCH(B18,'Metabase Lookup'!$A:$A,0)),"",IF(INDEX('Metabase Lookup'!$D:$D,MATCH(B18,'Metabase Lookup'!$A:$A,0))="","",INDEX('Metabase Lookup'!$D:$D,MATCH(B18,'Metabase Lookup'!$A:$A,0)))) | Y18: =IF(ISNUMBER(W18),IF(W18>0,"Yes","No"),"Pending") | Z18: TID had stray spaces/line breaks (cleaned); Driver not identified (OPS account)
A19: 18 | B19: TNGE126027123707211000 | C19: 265742627200 | D19: 46286.448 | E19: 46286 | F19: Mon | G19: Southern | H19: GLG | I19: GLG - OPS - ENGKU | J19: OPS (generic hub account) | K19: 91845006 | L19: 1 | M19: LM | N19: Fake Fail | O19: No call / call log missing | P19: Yes | Q19: No | R19: no call log attach and no site photo for customer address | S19: Zati | T19: =COUNTIF($B$2:$B$499,B19) | U19: =COUNTIF($I$2:$I$499,I19) | V19: =IF(ISNA(MATCH(B19,'Metabase Lookup'!$A:$A,0)),"Not found",IF(INDEX('Metabase Lookup'!$B:$B,MATCH(B19,'Metabase Lookup'!$A:$A,0))="","Pending",INDEX('Metabase Lookup'!$B:$B,MATCH(B19,'Metabase Lookup'!$A:$A,0)))) | W19: =IF(ISNA(MATCH(B19,'Metabase Lookup'!$A:$A,0)),"Not found",IF(INDEX('Metabase Lookup'!$C:$C,MATCH(B19,'Metabase Lookup'!$A:$A,0))="","Pending",INDEX('Metabase Lookup'!$C:$C,MATCH(B19,'Metabase Lookup'!$A:$A,0)))) | X19: =IF(ISNA(MATCH(B19,'Metabase Lookup'!$A:$A,0)),"",IF(INDEX('Metabase Lookup'!$D:$D,MATCH(B19,'Metabase Lookup'!$A:$A,0))="","",INDEX('Metabase Lookup'!$D:$D,MATCH(B19,'Metabase Lookup'!$A:$A,0)))) | Y19: =IF(ISNUMBER(W19),IF(W19>0,"Yes","No"),"Pending") | Z19: Driver not identified (OPS account)
A20: 19 | B20: TESMX1549981438514819072 | C20: 266782640335 | D20: 46286.448 | E20: 46286 | F20: Mon | G20: North West | H20: TPG | I20: TPG - HR - ROZAINI MUSA | J20: HR (named) | K20: 91834761, 91842435, 91849708 | L20: 3 | M20: LM | N20: Fake Fail | O20: Recycled / manipulated POD | P20: No | Q20: No | R20: Driver using copied POD, no number showed up. | S20: Syak | T20: =COUNTIF($B$2:$B$499,B20) | U20: =COUNTIF($I$2:$I$499,I20) | V20: =IF(ISNA(MATCH(B20,'Metabase Lookup'!$A:$A,0)),"Not found",IF(INDEX('Metabase Lookup'!$B:$B,MATCH(B20,'Metabase Lookup'!$A:$A,0))="","Pending",INDEX('Metabase Lookup'!$B:$B,MATCH(B20,'Metabase Lookup'!$A:$A,0)))) | W20: =IF(ISNA(MATCH(B20,'Metabase Lookup'!$A:$A,0)),"Not found",IF(INDEX('Metabase Lookup'!$C:$C,MATCH(B20,'Metabase Lookup'!$A:$A,0))="","Pending",INDEX('Metabase Lookup'!$C:$C,MATCH(B20,'Metabase Lookup'!$A:$A,0)))) | X20: =IF(ISNA(MATCH(B20,'Metabase Lookup'!$A:$A,0)),"",IF(INDEX('Metabase Lookup'!$D:$D,MATCH(B20,'Metabase Lookup'!$A:$A,0))="","",INDEX('Metabase Lookup'!$D:$D,MATCH(B20,'Metabase Lookup'!$A:$A,0)))) | Y20: =IF(ISNUMBER(W20),IF(W20>0,"Yes","No"),"Pending") | Z20: Multiple route IDs
A21: 20 | B21: ZRP859473225359 | C21: 262282626023 | D21: 46286.45 | E21: 46286 | F21: Mon | G21: KV | H21: OUG | I21: OUG - ID - NASRUL FIKRI | J21: ID (named driver) | K21: 91835496 | L21: 1 | M21: LM | N21: Failed pick-up | R21: RPU parcel and pickup failed on 18/9. driver not call the customer. | S21: Zati | T21: =COUNTIF($B$2:$B$499,B21) | U21: =COUNTIF($I$2:$I$499,I21) | V21: =IF(ISNA(MATCH(B21,'Metabase Lookup'!$A:$A,0)),"Not found",IF(INDEX('Metabase Lookup'!$B:$B,MATCH(B21,'Metabase Lookup'!$A:$A,0))="","Pending",INDEX('Metabase Lookup'!$B:$B,MATCH(B21,'Metabase Lookup'!$A:$A,0)))) | W21: =IF(ISNA(MATCH(B21,'Metabase Lookup'!$A:$A,0)),"Not found",IF(INDEX('Metabase Lookup'!$C:$C,MATCH(B21,'Metabase Lookup'!$A:$A,0))="","Pending",INDEX('Metabase Lookup'!$C:$C,MATCH(B21,'Metabase Lookup'!$A:$A,0)))) | X21: =IF(ISNA(MATCH(B21,'Metabase Lookup'!$A:$A,0)),"",IF(INDEX('Metabase Lookup'!$D:$D,MATCH(B21,'Metabase Lookup'!$A:$A,0))="","",INDEX('Metabase Lookup'!$D:$D,MATCH(B21,'Metabase Lookup'!$A:$A,0)))) | Y21: =IF(ISNUMBER(W21),IF(W21>0,"Yes","No"),"Pending")
A22: 21 | B22: NVMYPSITI000008262 | C22: 263192628067 | D22: 46286.451 | E22: 46286 | F22: Mon | G22: North East | H22: CHU | I22: Mohammad Abdullah | J22: Name only (no hub/code) | K22: 91833111 | L22: 1 | M22: LM | N22: Pull Out Route (POR) | R22: PULL OUT OF ROUTE by Mohammad Abdullah on 2026-09-19 08:30:11 | S22: Zati | T22: =COUNTIF($B$2:$B$499,B22) | U22: =COUNTIF($I$2:$I$499,I22) | V22: =IF(ISNA(MATCH(B22,'Metabase Lookup'!$A:$A,0)),"Not found",IF(INDEX('Metabase Lookup'!$B:$B,MATCH(B22,'Metabase Lookup'!$A:$A,0))="","Pending",INDEX('Metabase Lookup'!$B:$B,MATCH(B22,'Metabase Lookup'!$A:$A,0)))) | W22: =IF(ISNA(MATCH(B22,'Metabase Lookup'!$A:$A,0)),"Not found",IF(INDEX('Metabase Lookup'!$C:$C,MATCH(B22,'Metabase Lookup'!$A:$A,0))="","Pending",INDEX('Metabase Lookup'!$C:$C,MATCH(B22,'Metabase Lookup'!$A:$A,0)))) | X22: =IF(ISNA(MATCH(B22,'Metabase Lookup'!$A:$A,0)),"",IF(INDEX('Metabase Lookup'!$D:$D,MATCH(B22,'Metabase Lookup'!$A:$A,0))="","",INDEX('Metabase Lookup'!$D:$D,MATCH(B22,'Metabase Lookup'!$A:$A,0)))) | Y22: =IF(ISNUMBER(W22),IF(W22>0,"Yes","No"),"Pending")
A23: 22 | B23: NVMYMZ0N3000028117 | C23: 269032647217 | D23: 46286.455 | E23: 46286 | F23: Mon | G23: KV | H23: OUG | I23: OUG - ID - MUHAMAR | J23: ID (named driver) | K23: 91851654 | L23: 1 | M23: LM | N23: Parcel Dumping | R23: Driver not notifying cust after delivered the parcel | S23: Syak | T23: =COUNTIF($B$2:$B$499,B23) | U23: =COUNTIF($I$2:$I$499,I23) | V23: =IF(ISNA(MATCH(B23,'Metabase Lookup'!$A:$A,0)),"Not found",IF(INDEX('Metabase Lookup'!$B:$B,MATCH(B23,'Metabase Lookup'!$A:$A,0))="","Pending",INDEX('Metabase Lookup'!$B:$B,MATCH(B23,'Metabase Lookup'!$A:$A,0)))) | W23: =IF(ISNA(MATCH(B23,'Metabase Lookup'!$A:$A,0)),"Not found",IF(INDEX('Metabase Lookup'!$C:$C,MATCH(B23,'Metabase Lookup'!$A:$A,0))="","Pending",INDEX('Metabase Lookup'!$C:$C,MATCH(B23,'Metabase Lookup'!$A:$A,0)))) | X23: =IF(ISNA(MATCH(B23,'Metabase Lookup'!$A:$A,0)),"",IF(INDEX('Metabase Lookup'!$D:$D,MATCH(B23,'Metabase Lookup'!$A:$A,0))="","",INDEX('Metabase Lookup'!$D:$D,MATCH(B23,'Metabase Lookup'!$A:$A,0)))) | Y23: =IF(ISNUMBER(W23),IF(W23>0,"Yes","No"),"Pending")
A24: 23 | B24: ZNV253317945-1886 | C24: 263702637111 | D24: 46286.456 | E24: 46286 | F24: Mon | G24: Northern | H24: PSN | I24: PSN - ID - NOOR AZZAMIRA | J24: ID (named driver) | K24: 91824410 | L24: 1 | M24: LM | N24: Fake Fail | O24: Invalid location / site photo | P24: Yes | Q24: No | R24: invalid site photo , cannot classified this is the correct house | S24: Yana | T24: =COUNTIF($B$2:$B$499,B24) | U24: =COUNTIF($I$2:$I$499,I24) | V24: =IF(ISNA(MATCH(B24,'Metabase Lookup'!$A:$A,0)),"Not found",IF(INDEX('Metabase Lookup'!$B:$B,MATCH(B24,'Metabase Lookup'!$A:$A,0))="","Pending",INDEX('Metabase Lookup'!$B:$B,MATCH(B24,'Metabase Lookup'!$A:$A,0)))) | W24: =IF(ISNA(MATCH(B24,'Metabase Lookup'!$A:$A,0)),"Not found",IF(INDEX('Metabase Lookup'!$C:$C,MATCH(B24,'Metabase Lookup'!$A:$A,0))="","Pending",INDEX('Metabase Lookup'!$C:$C,MATCH(B24,'Metabase Lookup'!$A:$A,0)))) | X24: =IF(ISNA(MATCH(B24,'Metabase Lookup'!$A:$A,0)),"",IF(INDEX('Metabase Lookup'!$D:$D,MATCH(B24,'Metabase Lookup'!$A:$A,0))="","",INDEX('Metabase Lookup'!$D:$D,MATCH(B24,'Metabase Lookup'!$A:$A,0)))) | Y24: =IF(ISNUMBER(W24),IF(W24>0,"Yes","No"),"Pending")
A25: 24 | B25: ZRP859373225311 | C25: 269352622436 | D25: 46286.46 | E25: 46286 | F25: Mon | G25: Northern | H25: GEO | I25: GEO - MES - ANWAR | J25: Other coded | K25: 91833914, 91842995 | L25: 2 | M25: LM | N25: Failed pick-up | R25: no location address attach by driver | S25: Zati | T25: =COUNTIF($B$2:$B$499,B25) | U25: =COUNTIF($I$2:$I$499,I25) | V25: =IF(ISNA(MATCH(B25,'Metabase Lookup'!$A:$A,0)),"Not found",IF(INDEX('Metabase Lookup'!$B:$B,MATCH(B25,'Metabase Lookup'!$A:$A,0))="","Pending",INDEX('Metabase Lookup'!$B:$B,MATCH(B25,'Metabase Lookup'!$A:$A,0)))) | W25: =IF(ISNA(MATCH(B25,'Metabase Lookup'!$A:$A,0)),"Not found",IF(INDEX('Metabase Lookup'!$C:$C,MATCH(B25,'Metabase Lookup'!$A:$A,0))="","Pending",INDEX('Metabase Lookup'!$C:$C,MATCH(B25,'Metabase Lookup'!$A:$A,0)))) | X25: =IF(ISNA(MATCH(B25,'Metabase Lookup'!$A:$A,0)),"",IF(INDEX('Metabase Lookup'!$D:$D,MATCH(B25,'Metabase Lookup'!$A:$A,0))="","",INDEX('Metabase Lookup'!$D:$D,MATCH(B25,'Metabase Lookup'!$A:$A,0)))) | Y25: =IF(ISNUMBER(W25),IF(W25>0,"Yes","No"),"Pending") | Z25: Multiple route IDs
A26: 25 | B26: ZNV946823440-8240-BKS | C26: 260352624803 | D26: 46286.462 | E26: 46286 | F26: Mon | G26: Southern | H26: NSJ | I26: OPS - NSJ | J26: OPS (generic hub account) | K26: 91844859 | L26: 1 | M26: LM | N26: Fake Fail | O26: No call / call log missing | P26: No | Q26: No | R26: no call log attach and pod is invalid | S26: Zati | T26: =COUNTIF($B$2:$B$499,B26) | U26: =COUNTIF($I$2:$I$499,I26) | V26: =IF(ISNA(MATCH(B26,'Metabase Lookup'!$A:$A,0)),"Not found",IF(INDEX('Metabase Lookup'!$B:$B,MATCH(B26,'Metabase Lookup'!$A:$A,0))="","Pending",INDEX('Metabase Lookup'!$B:$B,MATCH(B26,'Metabase Lookup'!$A:$A,0)))) | W26: =IF(ISNA(MATCH(B26,'Metabase Lookup'!$A:$A,0)),"Not found",IF(INDEX('Metabase Lookup'!$C:$C,MATCH(B26,'Metabase Lookup'!$A:$A,0))="","Pending",INDEX('Metabase Lookup'!$C:$C,MATCH(B26,'Metabase Lookup'!$A:$A,0)))) | X26: =IF(ISNA(MATCH(B26,'Metabase Lookup'!$A:$A,0)),"",IF(INDEX('Metabase Lookup'!$D:$D,MATCH(B26,'Metabase Lookup'!$A:$A,0))="","",INDEX('Metabase Lookup'!$D:$D,MATCH(B26,'Metabase Lookup'!$A:$A,0)))) | Y26: =IF(ISNUMBER(W26),IF(W26>0,"Yes","No"),"Pending") | Z26: Driver not identified (OPS account)
A27: 26 | B27: ZMYITJ6MMPDS-2777789 | C27: 265032622937 | D27: 46286.464 | E27: 46286 | F27: Mon | G27: KV | H27: OUG | I27: OPS - OUG | J27: OPS (generic hub account) | K27: 91836449 | L27: 1 | M27: LM | N27: Fake Fail | O27: Wrong number called | P27: No | Q27: No | R27: Call log attach not show customer contact number | S27: Zati | T27: =COUNTIF($B$2:$B$499,B27) | U27: =COUNTIF($I$2:$I$499,I27) | V27: =IF(ISNA(MATCH(B27,'Metabase Lookup'!$A:$A,0)),"Not found",IF(INDEX('Metabase Lookup'!$B:$B,MATCH(B27,'Metabase Lookup'!$A:$A,0))="","Pending",INDEX('Metabase Lookup'!$B:$B,MATCH(B27,'Metabase Lookup'!$A:$A,0)))) | W27: =IF(ISNA(MATCH(B27,'Metabase Lookup'!$A:$A,0)),"Not found",IF(INDEX('Metabase Lookup'!$C:$C,MATCH(B27,'Metabase Lookup'!$A:$A,0))="","Pending",INDEX('Metabase Lookup'!$C:$C,MATCH(B27,'Metabase Lookup'!$A:$A,0)))) | X27: =IF(ISNA(MATCH(B27,'Metabase Lookup'!$A:$A,0)),"",IF(INDEX('Metabase Lookup'!$D:$D,MATCH(B27,'Metabase Lookup'!$A:$A,0))="","",INDEX('Metabase Lookup'!$D:$D,MATCH(B27,'Metabase Lookup'!$A:$A,0)))) | Y27: =IF(ISNUMBER(W27),IF(W27>0,"Yes","No"),"Pending") | Z27: Driver not identified (OPS account)
A28: 27 | B28: ZNV946832382-8599 | C28: 268002630146 | D28: 46286.465 | E28: 46286 | F28: Mon | G28: KV | H28: DSA | I28: OPS - DSA | J28: OPS (generic hub account) | K28: 91844986 | L28: 1 | M28: LM | N28: Fake Fail | O28: Invalid POD (no detail) | P28: No | Q28: Yes | R28: invalid POD, failed under ops | S28: Yana | T28: =COUNTIF($B$2:$B$499,B28) | U28: =COUNTIF($I$2:$I$499,I28) | V28: =IF(ISNA(MATCH(B28,'Metabase Lookup'!$A:$A,0)),"Not found",IF(INDEX('Metabase Lookup'!$B:$B,MATCH(B28,'Metabase Lookup'!$A:$A,0))="","Pending",INDEX('Metabase Lookup'!$B:$B,MATCH(B28,'Metabase Lookup'!$A:$A,0)))) | W28: =IF(ISNA(MATCH(B28,'Metabase Lookup'!$A:$A,0)),"Not found",IF(INDEX('Metabase Lookup'!$C:$C,MATCH(B28,'Metabase Lookup'!$A:$A,0))="","Pending",INDEX('Metabase Lookup'!$C:$C,MATCH(B28,'Metabase Lookup'!$A:$A,0)))) | X28: =IF(ISNA(MATCH(B28,'Metabase Lookup'!$A:$A,0)),"",IF(INDEX('Metabase Lookup'!$D:$D,MATCH(B28,'Metabase Lookup'!$A:$A,0))="","",INDEX('Metabase Lookup'!$D:$D,MATCH(B28,'Metabase Lookup'!$A:$A,0)))) | Y28: =IF(ISNUMBER(W28),IF(W28>0,"Yes","No"),"Pending") | Z28: Driver not identified (OPS account)
A29: 28 | B29: TNGDV2609136945139660 | C29: 264052642446 | D29: 46286.465 | E29: 46286 | F29: Mon | G29: KV | H29: SHM | I29: OPS - SHM | J29: OPS (generic hub account) | K29: 91836515 | L29: 1 | M29: LM | N29: Fake Fail | O29: No call / call log missing | P29: No | Q29: No | R29: no call log attach and pod is invalid | S29: Zati | T29: =COUNTIF($B$2:$B$499,B29) | U29: =COUNTIF($I$2:$I$499,I29) | V29: =IF(ISNA(MATCH(B29,'Metabase Lookup'!$A:$A,0)),"Not found",IF(INDEX('Metabase Lookup'!$B:$B,MATCH(B29,'Metabase Lookup'!$A:$A,0))="","Pending",INDEX('Metabase Lookup'!$B:$B,MATCH(B29,'Metabase Lookup'!$A:$A,0)))) | W29: =IF(ISNA(MATCH(B29,'Metabase Lookup'!$A:$A,0)),"Not found",IF(INDEX('Metabase Lookup'!$C:$C,MATCH(B29,'Metabase Lookup'!$A:$A,0))="","Pending",INDEX('Metabase Lookup'!$C:$C,MATCH(B29,'Metabase Lookup'!$A:$A,0)))) | X29: =IF(ISNA(MATCH(B29,'Metabase Lookup'!$A:$A,0)),"",IF(INDEX('Metabase Lookup'!$D:$D,MATCH(B29,'Metabase Lookup'!$A:$A,0))="","",INDEX('Metabase Lookup'!$D:$D,MATCH(B29,'Metabase Lookup'!$A:$A,0)))) | Y29: =IF(ISNUMBER(W29),IF(W29>0,"Yes","No"),"Pending") | Z29: Driver not identified (OPS account)
A30: 29 | B30: NVMYHILAL00HL23336 | C30: 267652647673 | D30: 46286.467 | E30: 46286 | F30: Mon | G30: KV | H30: SHA | I30: SHA - OPS - SHA | J30: OPS (generic hub account) | K30: 91848706 | L30: 1 | M30: LM | N30: Fake Fail | O30: Wrong number called | P30: No | Q30: No | R30: call log attach is not belong to customer | S30: Zati | T30: =COUNTIF($B$2:$B$499,B30) | U30: =COUNTIF($I$2:$I$499,I30) | V30: =IF(ISNA(MATCH(B30,'Metabase Lookup'!$A:$A,0)),"Not found",IF(INDEX('Metabase Lookup'!$B:$B,MATCH(B30,'Metabase Lookup'!$A:$A,0))="","Pending",INDEX('Metabase Lookup'!$B:$B,MATCH(B30,'Metabase Lookup'!$A:$A,0)))) | W30: =IF(ISNA(MATCH(B30,'Metabase Lookup'!$A:$A,0)),"Not found",IF(INDEX('Metabase Lookup'!$C:$C,MATCH(B30,'Metabase Lookup'!$A:$A,0))="","Pending",INDEX('Metabase Lookup'!$C:$C,MATCH(B30,'Metabase Lookup'!$A:$A,0)))) | X30: =IF(ISNA(MATCH(B30,'Metabase Lookup'!$A:$A,0)),"",IF(INDEX('Metabase Lookup'!$D:$D,MATCH(B30,'Metabase Lookup'!$A:$A,0))="","",INDEX('Metabase Lookup'!$D:$D,MATCH(B30,'Metabase Lookup'!$A:$A,0)))) | Y30: =IF(ISNUMBER(W30),IF(W30>0,"Yes","No"),"Pending") | Z30: Driver not identified (OPS account)
A31: 30 | B31: NLMYWA04659534 | C31: 263882645868 | D31: 46286.469 | E31: 46286 | F31: Mon | G31: KV | H31: BTR | I31: Norman Razak | J31: Name only (no hub/code) | K31: 91847382 | L31: 1 | M31: LM | N31: Pull Out Route (POR) | R31: PULL OUT OF ROUTE by Norman Razak on 2026-09-20 23:40:50 | S31: Zati | T31: =COUNTIF($B$2:$B$499,B31) | U31: =COUNTIF($I$2:$I$499,I31) | V31: =IF(ISNA(MATCH(B31,'Metabase Lookup'!$A:$A,0)),"Not found",IF(INDEX('Metabase Lookup'!$B:$B,MATCH(B31,'Metabase Lookup'!$A:$A,0))="","Pending",INDEX('Metabase Lookup'!$B:$B,MATCH(B31,'Metabase Lookup'!$A:$A,0)))) | W31: =IF(ISNA(MATCH(B31,'Metabase Lookup'!$A:$A,0)),"Not found",IF(INDEX('Metabase Lookup'!$C:$C,MATCH(B31,'Metabase Lookup'!$A:$A,0))="","Pending",INDEX('Metabase Lookup'!$C:$C,MATCH(B31,'Metabase Lookup'!$A:$A,0)))) | X31: =IF(ISNA(MATCH(B31,'Metabase Lookup'!$A:$A,0)),"",IF(INDEX('Metabase Lookup'!$D:$D,MATCH(B31,'Metabase Lookup'!$A:$A,0))="","",INDEX('Metabase Lookup'!$D:$D,MATCH(B31,'Metabase Lookup'!$A:$A,0)))) | Y31: =IF(ISNUMBER(W31),IF(W31>0,"Yes","No"),"Pending")
A32: 31 | B32: NVMYKILATWK0076807 | C32: 260612649160 | D32: 46286.475 | E32: 46286 | F32: Mon | G32: Southern | H32: LKN | I32: Hanzholah Hasani | J32: Name only (no hub/code) | K32: 91845093 | L32: 1 | M32: LM | N32: Pull Out Route (POR) | R32: PULL OUT OF ROUTE by Hanzholah Hasani on 2026-09-20 10:15:01 | S32: Zati | T32: =COUNTIF($B$2:$B$499,B32) | U32: =COUNTIF($I$2:$I$499,I32) | V32: =IF(ISNA(MATCH(B32,'Metabase Lookup'!$A:$A,0)),"Not found",IF(INDEX('Metabase Lookup'!$B:$B,MATCH(B32,'Metabase Lookup'!$A:$A,0))="","Pending",INDEX('Metabase Lookup'!$B:$B,MATCH(B32,'Metabase Lookup'!$A:$A,0)))) | W32: =IF(ISNA(MATCH(B32,'Metabase Lookup'!$A:$A,0)),"Not found",IF(INDEX('Metabase Lookup'!$C:$C,MATCH(B32,'Metabase Lookup'!$A:$A,0))="","Pending",INDEX('Metabase Lookup'!$C:$C,MATCH(B32,'Metabase Lookup'!$A:$A,0)))) | X32: =IF(ISNA(MATCH(B32,'Metabase Lookup'!$A:$A,0)),"",IF(INDEX('Metabase Lookup'!$D:$D,MATCH(B32,'Metabase Lookup'!$A:$A,0))="","",INDEX('Metabase Lookup'!$D:$D,MATCH(B32,'Metabase Lookup'!$A:$A,0)))) | Y32: =IF(ISNUMBER(W32),IF(W32>0,"Yes","No"),"Pending")
A33: 32 | B33: AMNV005963959 | C33: 269502643639 | D33: 46286.477 | E33: 46286 | F33: Mon | G33: Northern | H33: AOR | I33: AOR - FM - Ihsan Rashid | J33: FM (first-mile) | K33: 91844628 | L33: 1 | M33: LM | N33: Fake Fail | O33: Invalid POD (no detail) | P33: No | Q33: No | R33: Invalid POD | S33: Naveen | T33: =COUNTIF($B$2:$B$499,B33) | U33: =COUNTIF($I$2:$I$499,I33) | V33: =IF(ISNA(MATCH(B33,'Metabase Lookup'!$A:$A,0)),"Not found",IF(INDEX('Metabase Lookup'!$B:$B,MATCH(B33,'Metabase Lookup'!$A:$A,0))="","Pending",INDEX('Metabase Lookup'!$B:$B,MATCH(B33,'Metabase Lookup'!$A:$A,0)))) | W33: =IF(ISNA(MATCH(B33,'Metabase Lookup'!$A:$A,0)),"Not found",IF(INDEX('Metabase Lookup'!$C:$C,MATCH(B33,'Metabase Lookup'!$A:$A,0))="","Pending",INDEX('Metabase Lookup'!$C:$C,MATCH(B33,'Metabase Lookup'!$A:$A,0)))) | X33: =IF(ISNA(MATCH(B33,'Metabase Lookup'!$A:$A,0)),"",IF(INDEX('Metabase Lookup'!$D:$D,MATCH(B33,'Metabase Lookup'!$A:$A,0))="","",INDEX('Metabase Lookup'!$D:$D,MATCH(B33,'Metabase Lookup'!$A:$A,0)))) | Y33: =IF(ISNUMBER(W33),IF(W33>0,"Yes","No"),"Pending")
A34: 33 | B34: ADI111550482187476107264 | C34: 260452642580 | D34: 46286.48 | E34: 46286 | F34: Mon | G34: KV | H34: SHA | I34: SHA - OPS - SHA | J34: OPS (generic hub account) | K34: 91848706 | L34: 1 | M34: LM | N34: Fake Fail | O34: Wrong number called | P34: No | Q34: No | R34: driver attach wrong call log not belong customer | S34: Zati | T34: =COUNTIF($B$2:$B$499,B34) | U34: =COUNTIF($I$2:$I$499,I34) | V34: =IF(ISNA(MATCH(B34,'Metabase Lookup'!$A:$A,0)),"Not found",IF(INDEX('Metabase Lookup'!$B:$B,MATCH(B34,'Metabase Lookup'!$A:$A,0))="","Pending",INDEX('Metabase Lookup'!$B:$B,MATCH(B34,'Metabase Lookup'!$A:$A,0)))) | W34: =IF(ISNA(MATCH(B34,'Metabase Lookup'!$A:$A,0)),"Not found",IF(INDEX('Metabase Lookup'!$C:$C,MATCH(B34,'Metabase Lookup'!$A:$A,0))="","Pending",INDEX('Metabase Lookup'!$C:$C,MATCH(B34,'Metabase Lookup'!$A:$A,0)))) | X34: =IF(ISNA(MATCH(B34,'Metabase Lookup'!$A:$A,0)),"",IF(INDEX('Metabase Lookup'!$D:$D,MATCH(B34,'Metabase Lookup'!$A:$A,0))="","",INDEX('Metabase Lookup'!$D:$D,MATCH(B34,'Metabase Lookup'!$A:$A,0)))) | Y34: =IF(ISNUMBER(W34),IF(W34>0,"Yes","No"),"Pending") | Z34: Driver not identified (OPS account)
A35: 34 | B35: MAILB1549313460283060224 | C35: 265662644805 | D35: 46286.481 | E35: 46286 | F35: Mon | G35: KV | H35: STL | I35: Najib Halif | J35: Name only (no hub/code) | K35: 91836491 | L35: 1 | M35: LM | N35: Pull Out Route (POR) | R35: DRIVER INBOUND SCAN > 2026-09-18 17:36:40 PULL OUT OF ROUTE > 2026-09-21 08:53:44 | S35: Naveen | T35: =COUNTIF($B$2:$B$499,B35) | U35: =COUNTIF($I$2:$I$499,I35) | V35: =IF(ISNA(MATCH(B35,'Metabase Lookup'!$A:$A,0)),"Not found",IF(INDEX('Metabase Lookup'!$B:$B,MATCH(B35,'Metabase Lookup'!$A:$A,0))="","Pending",INDEX('Metabase Lookup'!$B:$B,MATCH(B35,'Metabase Lookup'!$A:$A,0)))) | W35: =IF(ISNA(MATCH(B35,'Metabase Lookup'!$A:$A,0)),"Not found",IF(INDEX('Metabase Lookup'!$C:$C,MATCH(B35,'Metabase Lookup'!$A:$A,0))="","Pending",INDEX('Metabase Lookup'!$C:$C,MATCH(B35,'Metabase Lookup'!$A:$A,0)))) | X35: =IF(ISNA(MATCH(B35,'Metabase Lookup'!$A:$A,0)),"",IF(INDEX('Metabase Lookup'!$D:$D,MATCH(B35,'Metabase Lookup'!$A:$A,0))="","",INDEX('Metabase Lookup'!$D:$D,MATCH(B35,'Metabase Lookup'!$A:$A,0)))) | Y35: =IF(ISNUMBER(W35),IF(W35>0,"Yes","No"),"Pending") | Z35: TID had stray spaces/line breaks (cleaned)
A36: 35 | B36: TAIN1546068998241939456 | C36: 265572649548 | D36: 46286.482 | E36: 46286 | F36: Mon | G36: Northern | H36: BTS | I36: BTS - OPS - PENAGA | J36: OPS (generic hub account) | K36: 91836653 | L36: 1 | M36: LM | N36: Fake Fail | O36: Wrong number called | P36: No | Q36: No | R36: driver contact different number | S36: Hartini | T36: =COUNTIF($B$2:$B$499,B36) | U36: =COUNTIF($I$2:$I$499,I36) | V36: =IF(ISNA(MATCH(B36,'Metabase Lookup'!$A:$A,0)),"Not found",IF(INDEX('Metabase Lookup'!$B:$B,MATCH(B36,'Metabase Lookup'!$A:$A,0))="","Pending",INDEX('Metabase Lookup'!$B:$B,MATCH(B36,'Metabase Lookup'!$A:$A,0)))) | W36: =IF(ISNA(MATCH(B36,'Metabase Lookup'!$A:$A,0)),"Not found",IF(INDEX('Metabase Lookup'!$C:$C,MATCH(B36,'Metabase Lookup'!$A:$A,0))="","Pending",INDEX('Metabase Lookup'!$C:$C,MATCH(B36,'Metabase Lookup'!$A:$A,0)))) | X36: =IF(ISNA(MATCH(B36,'Metabase Lookup'!$A:$A,0)),"",IF(INDEX('Metabase Lookup'!$D:$D,MATCH(B36,'Metabase Lookup'!$A:$A,0))="","",INDEX('Metabase Lookup'!$D:$D,MATCH(B36,'Metabase Lookup'!$A:$A,0)))) | Y36: =IF(ISNUMBER(W36),IF(W36>0,"Yes","No"),"Pending") | Z36: Driver not identified (OPS account)
A37: 36 | B37: NVMYTNAMR000000532 | C37: 260362647323 | D37: 46286.483 | E37: 46286 | F37: Mon | G37: Southern | H37: HTM | I37: HTM - ID - OPS | J37: OPS (generic hub account) | K37: 91843077 | L37: 1 | M37: LM | N37: Fake Fail | O37: Invalid location / site photo | P37: Yes | Q37: No | R37: Cust claim pod is not cust place | S37: Naveen | T37: =COUNTIF($B$2:$B$499,B37) | U37: =COUNTIF($I$2:$I$499,I37) | V37: =IF(ISNA(MATCH(B37,'Metabase Lookup'!$A:$A,0)),"Not found",IF(INDEX('Metabase Lookup'!$B:$B,MATCH(B37,'Metabase Lookup'!$A:$A,0))="","Pending",INDEX('Metabase Lookup'!$B:$B,MATCH(B37,'Metabase Lookup'!$A:$A,0)))) | W37: =IF(ISNA(MATCH(B37,'Metabase Lookup'!$A:$A,0)),"Not found",IF(INDEX('Metabase Lookup'!$C:$C,MATCH(B37,'Metabase Lookup'!$A:$A,0))="","Pending",INDEX('Metabase Lookup'!$C:$C,MATCH(B37,'Metabase Lookup'!$A:$A,0)))) | X37: =IF(ISNA(MATCH(B37,'Metabase Lookup'!$A:$A,0)),"",IF(INDEX('Metabase Lookup'!$D:$D,MATCH(B37,'Metabase Lookup'!$A:$A,0))="","",INDEX('Metabase Lookup'!$D:$D,MATCH(B37,'Metabase Lookup'!$A:$A,0)))) | Y37: =IF(ISNUMBER(W37),IF(W37>0,"Yes","No"),"Pending") | Z37: Driver not identified (OPS account)
A38: 37 | B38: MOOK1550361206561648640 | C38: 263382649683 | D38: 46286.487 | E38: 46286 | F38: Mon | G38: Northern | H38: KLM | I38: KLM - ID - HAFIZI HABIBON | KLM - ID - ONG WEI | J38: Multiple drivers | K38: 91841281, 91849300 | L38: 2 | M38: LM | N38: Fake Fail | O38: Invalid location / site photo | P38: Yes | Q38: No | R38: driver attach wrong location and not customer house | S38: Zati | T38: =COUNTIF($B$2:$B$499,B38) | U38: =COUNTIF($I$2:$I$499,I38) | V38: =IF(ISNA(MATCH(B38,'Metabase Lookup'!$A:$A,0)),"Not found",IF(INDEX('Metabase Lookup'!$B:$B,MATCH(B38,'Metabase Lookup'!$A:$A,0))="","Pending",INDEX('Metabase Lookup'!$B:$B,MATCH(B38,'Metabase Lookup'!$A:$A,0)))) | W38: =IF(ISNA(MATCH(B38,'Metabase Lookup'!$A:$A,0)),"Not found",IF(INDEX('Metabase Lookup'!$C:$C,MATCH(B38,'Metabase Lookup'!$A:$A,0))="","Pending",INDEX('Metabase Lookup'!$C:$C,MATCH(B38,'Metabase Lookup'!$A:$A,0)))) | X38: =IF(ISNA(MATCH(B38,'Metabase Lookup'!$A:$A,0)),"",IF(INDEX('Metabase Lookup'!$D:$D,MATCH(B38,'Metabase Lookup'!$A:$A,0))="","",INDEX('Metabase Lookup'!$D:$D,MATCH(B38,'Metabase Lookup'!$A:$A,0)))) | Y38: =IF(ISNUMBER(W38),IF(W38>0,"Yes","No"),"Pending") | Z38: Multiple drivers in one row; Multiple route IDs
A39: 38 | B39: MYNJV70045865378/MYNJV70035605218 | C39: 265422646611 | D39: 46286.489 | E39: 46286 | F39: Mon | G39: KV | H39: SHA | I39: SHA - OPS - SHA | J39: OPS (generic hub account) | K39: 91826821 | L39: 1 | M39: LM | N39: Fake Fail | O39: Invalid POD (no detail) | P39: No | Q39: No | R39: POD invalid | S39: Naveen | T39: =COUNTIF($B$2:$B$499,B39) | U39: =COUNTIF($I$2:$I$499,I39) | V39: =IF(ISNA(MATCH(B39,'Metabase Lookup'!$A:$A,0)),"Not found",IF(INDEX('Metabase Lookup'!$B:$B,MATCH(B39,'Metabase Lookup'!$A:$A,0))="","Pending",INDEX('Metabase Lookup'!$B:$B,MATCH(B39,'Metabase Lookup'!$A:$A,0)))) | W39: =IF(ISNA(MATCH(B39,'Metabase Lookup'!$A:$A,0)),"Not found",IF(INDEX('Metabase Lookup'!$C:$C,MATCH(B39,'Metabase Lookup'!$A:$A,0))="","Pending",INDEX('Metabase Lookup'!$C:$C,MATCH(B39,'Metabase Lookup'!$A:$A,0)))) | X39: =IF(ISNA(MATCH(B39,'Metabase Lookup'!$A:$A,0)),"",IF(INDEX('Metabase Lookup'!$D:$D,MATCH(B39,'Metabase Lookup'!$A:$A,0))="","",INDEX('Metabase Lookup'!$D:$D,MATCH(B39,'Metabase Lookup'!$A:$A,0)))) | Y39: =IF(ISNUMBER(W39),IF(W39>0,"Yes","No"),"Pending") | Z39: TID had stray spaces/line breaks (cleaned); Driver not identified (OPS account)
A40: 39 | B40: NVMYNINJA002510859 | C40: 260812644722 | D40: 46286.495 | E40: 46286 | F40: Mon | G40: North West | H40: BAG | I40: Adam Haris | J40: Name only (no hub/code) | K40: 91851544 | L40: 1 | M40: LM | N40: Pull Out Route (POR) | R40: PULL OUT OF ROUTE by Adam Haris on 2026-09-21 09:21:55 | S40: Zati | T40: =COUNTIF($B$2:$B$499,B40) | U40: =COUNTIF($I$2:$I$499,I40) | V40: =IF(ISNA(MATCH(B40,'Metabase Lookup'!$A:$A,0)),"Not found",IF(INDEX('Metabase Lookup'!$B:$B,MATCH(B40,'Metabase Lookup'!$A:$A,0))="","Pending",INDEX('Metabase Lookup'!$B:$B,MATCH(B40,'Metabase Lookup'!$A:$A,0)))) | W40: =IF(ISNA(MATCH(B40,'Metabase Lookup'!$A:$A,0)),"Not found",IF(INDEX('Metabase Lookup'!$C:$C,MATCH(B40,'Metabase Lookup'!$A:$A,0))="","Pending",INDEX('Metabase Lookup'!$C:$C,MATCH(B40,'Metabase Lookup'!$A:$A,0)))) | X40: =IF(ISNA(MATCH(B40,'Metabase Lookup'!$A:$A,0)),"",IF(INDEX('Metabase Lookup'!$D:$D,MATCH(B40,'Metabase Lookup'!$A:$A,0))="","",INDEX('Metabase Lookup'!$D:$D,MATCH(B40,'Metabase Lookup'!$A:$A,0)))) | Y40: =IF(ISNUMBER(W40),IF(W40>0,"Yes","No"),"Pending") | Z40: TID logged more than once
...

Sheet Hub Scorecard
A1: Hub Scorecard — W39 (21–27 Sep 2026)
A2: Sorted by total complaints. All counts are live formulas on the Cases sheet.
A4: Rank | B4: Hub | C4: Region | D4: Total | E4: Fake Fail | F4: Fake Success | G4: Wrong Address | H4: POR | I4: Failed Pick-up | J4: Other | K4: % Fake Fail | L4: OPS-account Cases | M4: % Driver Not Identified | N4: Named Drivers Involved | O4: Share of Network
A5: 1 | B5: PJY | C5: KV | D5: =COUNTIF(Cases!$H$2:$H$499,B5) | E5: =COUNTIFS(Cases!$H$2:$H$499,$B5,Cases!$N$2:$N$499,"Fake Fail") | F5: =COUNTIFS(Cases!$H$2:$H$499,$B5,Cases!$N$2:$N$499,"Fake Success") | G5: =COUNTIFS(Cases!$H$2:$H$499,$B5,Cases!$N$2:$N$499,"Deliver to Wrong Address") | H5: =COUNTIFS(Cases!$H$2:$H$499,$B5,Cases!$N$2:$N$499,"Pull Out Route (POR)") | I5: =COUNTIFS(Cases!$H$2:$H$499,$B5,Cases!$N$2:$N$499,"Failed pick-up") | J5: =D5-SUM(E5:I5) | K5: =IF(D5=0,0,E5/D5) | L5: =COUNTIFS(Cases!$H$2:$H$499,$B5,Cases!$J$2:$J$499,"OPS (generic hub account)") | M5: =IF(D5=0,0,L5/D5) | N5: 1 | O5: =D5/COUNTA(Cases!$B$2:$B$499)
A6: 2 | B6: GLG | C6: Southern | D6: =COUNTIF(Cases!$H$2:$H$499,B6) | E6: =COUNTIFS(Cases!$H$2:$H$499,$B6,Cases!$N$2:$N$499,"Fake Fail") | F6: =COUNTIFS(Cases!$H$2:$H$499,$B6,Cases!$N$2:$N$499,"Fake Success") | G6: =COUNTIFS(Cases!$H$2:$H$499,$B6,Cases!$N$2:$N$499,"Deliver to Wrong Address") | H6: =COUNTIFS(Cases!$H$2:$H$499,$B6,Cases!$N$2:$N$499,"Pull Out Route (POR)") | I6: =COUNTIFS(Cases!$H$2:$H$499,$B6,Cases!$N$2:$N$499,"Failed pick-up") | J6: =D6-SUM(E6:I6) | K6: =IF(D6=0,0,E6/D6) | L6: =COUNTIFS(Cases!$H$2:$H$499,$B6,Cases!$J$2:$J$499,"OPS (generic hub account)") | M6: =IF(D6=0,0,L6/D6) | N6: 3 | O6: =D6/COUNTA(Cases!$B$2:$B$499)
A7: 3 | B7: KEM | C7: Southern | D7: =COUNTIF(Cases!$H$2:$H$499,B7) | E7: =COUNTIFS(Cases!$H$2:$H$499,$B7,Cases!$N$2:$N$499,"Fake Fail") | F7: =COUNTIFS(Cases!$H$2:$H$499,$B7,Cases!$N$2:$N$499,"Fake Success") | G7: =COUNTIFS(Cases!$H$2:$H$499,$B7,Cases!$N$2:$N$499,"Deliver to Wrong Address") | H7: =COUNTIFS(Cases!$H$2:$H$499,$B7,Cases!$N$2:$N$499,"Pull Out Route (POR)") | I7: =COUNTIFS(Cases!$H$2:$H$499,$B7,Cases!$N$2:$N$499,"Failed pick-up") | J7: =D7-SUM(E7:I7) | K7: =IF(D7=0,0,E7/D7) | L7: =COUNTIFS(Cases!$H$2:$H$499,$B7,Cases!$J$2:$J$499,"OPS (generic hub account)") | M7: =IF(D7=0,0,L7/D7) | N7: 6 | O7: =D7/COUNTA(Cases!$B$2:$B$499)
A8: 4 | B8: OUG | C8: KV | D8: =COUNTIF(Cases!$H$2:$H$499,B8) | E8: =COUNTIFS(Cases!$H$2:$H$499,$B8,Cases!$N$2:$N$499,"Fake Fail") | F8: =COUNTIFS(Cases!$H$2:$H$499,$B8,Cases!$N$2:$N$499,"Fake Success") | G8: =COUNTIFS(Cases!$H$2:$H$499,$B8,Cases!$N$2:$N$499,"Deliver to Wrong Address") | H8: =COUNTIFS(Cases!$H$2:$H$499,$B8,Cases!$N$2:$N$499,"Pull Out Route (POR)") | I8: =COUNTIFS(Cases!$H$2:$H$499,$B8,Cases!$N$2:$N$499,"Failed pick-up") | J8: =D8-SUM(E8:I8) | K8: =IF(D8=0,0,E8/D8) | L8: =COUNTIFS(Cases!$H$2:$H$499,$B8,Cases!$J$2:$J$499,"OPS (generic hub account)") | M8: =IF(D8=0,0,L8/D8) | N8: 6 | O8: =D8/COUNTA(Cases!$B$2:$B$499)
A9: 5 | B9: BTR | C9: KV | D9: =COUNTIF(Cases!$H$2:$H$499,B9) | E9: =COUNTIFS(Cases!$H$2:$H$499,$B9,Cases!$N$2:$N$499,"Fake Fail") | F9: =COUNTIFS(Cases!$H$2:$H$499,$B9,Cases!$N$2:$N$499,"Fake Success") | G9: =COUNTIFS(Cases!$H$2:$H$499,$B9,Cases!$N$2:$N$499,"Deliver to Wrong Address") | H9: =COUNTIFS(Cases!$H$2:$H$499,$B9,Cases!$N$2:$N$499,"Pull Out Route (POR)") | I9: =COUNTIFS(Cases!$H$2:$H$499,$B9,Cases!$N$2:$N$499,"Failed pick-up") | J9: =D9-SUM(E9:I9) | K9: =IF(D9=0,0,E9/D9) | L9: =COUNTIFS(Cases!$H$2:$H$499,$B9,Cases!$J$2:$J$499,"OPS (generic hub account)") | M9: =IF(D9=0,0,L9/D9) | N9: 6 | O9: =D9/COUNTA(Cases!$B$2:$B$499)
A10: 6 | B10: NSJ | C10: Southern | D10: =COUNTIF(Cases!$H$2:$H$499,B10) | E10: =COUNTIFS(Cases!$H$2:$H$499,$B10,Cases!$N$2:$N$499,"Fake Fail") | F10: =COUNTIFS(Cases!$H$2:$H$499,$B10,Cases!$N$2:$N$499,"Fake Success") | G10: =COUNTIFS(Cases!$H$2:$H$499,$B10,Cases!$N$2:$N$499,"Deliver to Wrong Address") | H10: =COUNTIFS(Cases!$H$2:$H$499,$B10,Cases!$N$2:$N$499,"Pull Out Route (POR)") | I10: =COUNTIFS(Cases!$H$2:$H$499,$B10,Cases!$N$2:$N$499,"Failed pick-up") | J10: =D10-SUM(E10:I10) | K10: =IF(D10=0,0,E10/D10) | L10: =COUNTIFS(Cases!$H$2:$H$499,$B10,Cases!$J$2:$J$499,"OPS (generic hub account)") | M10: =IF(D10=0,0,L10/D10) | N10: 1 | O10: =D10/COUNTA(Cases!$B$2:$B$499)
A11: 7 | B11: GEO | C11: Northern | D11: =COUNTIF(Cases!$H$2:$H$499,B11) | E11: =COUNTIFS(Cases!$H$2:$H$499,$B11,Cases!$N$2:$N$499,"Fake Fail") | F11: =COUNTIFS(Cases!$H$2:$H$499,$B11,Cases!$N$2:$N$499,"Fake Success") | G11: =COUNTIFS(Cases!$H$2:$H$499,$B11,Cases!$N$2:$N$499,"Deliver to Wrong Address") | H11: =COUNTIFS(Cases!$H$2:$H$499,$B11,Cases!$N$2:$N$499,"Pull Out Route (POR)") | I11: =COUNTIFS(Cases!$H$2:$H$499,$B11,Cases!$N$2:$N$499,"Failed pick-up") | J11: =D11-SUM(E11:I11) | K11: =IF(D11=0,0,E11/D11) | L11: =COUNTIFS(Cases!$H$2:$H$499,$B11,Cases!$J$2:$J$499,"OPS (generic hub account)") | M11: =IF(D11=0,0,L11/D11) | N11: 3 | O11: =D11/COUNTA(Cases!$B$2:$B$499)
A12: 8 | B12: BKW | C12: East MY | D12: =COUNTIF(Cases!$H$2:$H$499,B12) | E12: =COUNTIFS(Cases!$H$2:$H$499,$B12,Cases!$N$2:$N$499,"Fake Fail") | F12: =COUNTIFS(Cases!$H$2:$H$499,$B12,Cases!$N$2:$N$499,"Fake Success") | G12: =COUNTIFS(Cases!$H$2:$H$499,$B12,Cases!$N$2:$N$499,"Deliver to Wrong Address") | H12: =COUNTIFS(Cases!$H$2:$H$499,$B12,Cases!$N$2:$N$499,"Pull Out Route (POR)") | I12: =COUNTIFS(Cases!$H$2:$H$499,$B12,Cases!$N$2:$N$499,"Failed pick-up") | J12: =D12-SUM(E12:I12) | K12: =IF(D12=0,0,E12/D12) | L12: =COUNTIFS(Cases!$H$2:$H$499,$B12,Cases!$J$2:$J$499,"OPS (generic hub account)") | M12: =IF(D12=0,0,L12/D12) | N12: 4 | O12: =D12/COUNTA(Cases!$B$2:$B$499)
A13: 9 | B13: LKN | C13: Southern | D13: =COUNTIF(Cases!$H$2:$H$499,B13) | E13: =COUNTIFS(Cases!$H$2:$H$499,$B13,Cases!$N$2:$N$499,"Fake Fail") | F13: =COUNTIFS(Cases!$H$2:$H$499,$B13,Cases!$N$2:$N$499,"Fake Success") | G13: =COUNTIFS(Cases!$H$2:$H$499,$B13,Cases!$N$2:$N$499,"Deliver to Wrong Address") | H13: =COUNTIFS(Cases!$H$2:$H$499,$B13,Cases!$N$2:$N$499,"Pull Out Route (POR)") | I13: =COUNTIFS(Cases!$H$2:$H$499,$B13,Cases!$N$2:$N$499,"Failed pick-up") | J13: =D13-SUM(E13:I13) | K13: =IF(D13=0,0,E13/D13) | L13: =COUNTIFS(Cases!$H$2:$H$499,$B13,Cases!$J$2:$J$499,"OPS (generic hub account)") | M13: =IF(D13=0,0,L13/D13) | N13: 12 | O13: =D13/COUNTA(Cases!$B$2:$B$499)
A14: 10 | B14: DSA | C14: KV | D14: =COUNTIF(Cases!$H$2:$H$499,B14) | E14: =COUNTIFS(Cases!$H$2:$H$499,$B14,Cases!$N$2:$N$499,"Fake Fail") | F14: =COUNTIFS(Cases!$H$2:$H$499,$B14,Cases!$N$2:$N$499,"Fake Success") | G14: =COUNTIFS(Cases!$H$2:$H$499,$B14,Cases!$N$2:$N$499,"Deliver to Wrong Address") | H14: =COUNTIFS(Cases!$H$2:$H$499,$B14,Cases!$N$2:$N$499,"Pull Out Route (POR)") | I14: =COUNTIFS(Cases!$H$2:$H$499,$B14,Cases!$N$2:$N$499,"Failed pick-up") | J14: =D14-SUM(E14:I14) | K14: =IF(D14=0,0,E14/D14) | L14: =COUNTIFS(Cases!$H$2:$H$499,$B14,Cases!$J$2:$J$499,"OPS (generic hub account)") | M14: =IF(D14=0,0,L14/D14) | N14: 3 | O14: =D14/COUNTA(Cases!$B$2:$B$499)
A15: 11 | B15: TRM | C15: Southern | D15: =COUNTIF(Cases!$H$2:$H$499,B15) | E15: =COUNTIFS(Cases!$H$2:$H$499,$B15,Cases!$N$2:$N$499,"Fake Fail") | F15: =COUNTIFS(Cases!$H$2:$H$499,$B15,Cases!$N$2:$N$499,"Fake Success") | G15: =COUNTIFS(Cases!$H$2:$H$499,$B15,Cases!$N$2:$N$499,"Deliver to Wrong Address") | H15: =COUNTIFS(Cases!$H$2:$H$499,$B15,Cases!$N$2:$N$499,"Pull Out Route (POR)") | I15: =COUNTIFS(Cases!$H$2:$H$499,$B15,Cases!$N$2:$N$499,"Failed pick-up") | J15: =D15-SUM(E15:I15) | K15: =IF(D15=0,0,E15/D15) | L15: =COUNTIFS(Cases!$H$2:$H$499,$B15,Cases!$J$2:$J$499,"OPS (generic hub account)") | M15: =IF(D15=0,0,L15/D15) | N15: 4 | O15: =D15/COUNTA(Cases!$B$2:$B$499)
